Workbook

Sheet Overview
B2: George: 90-Day Marketing Dashboard
B3: Editable planning workbook. Yellow cells require business input. Base planning budget: R36,000.
B5: EXECUTIVE DECISION
B6: Recommended starting point: Base scenario (R36,000). Build the compliant conversion foundation in Month 1, test one acquisition path in Month 2, and concentrate on the winning topic and source in Month 3. Paid media remains approval-gated.
B9: WORKBOOK CONTENTS
B10: 90-Day Budget | C10: Scenario budgets, base monthly phasing, actual spend, and variance
B11: Weekly Plan | C11: 13-week objectives, actions, owners, gates, and status
B12: Content Calendar | C12: Three content items per week with approval controls
B13: KPI Tracker | C13: Weekly spend, traffic, enquiries, conversions, and economics
B14: Claim Register | C14: Claim evidence, scope, approval, and publication status
B15: Assumptions & Gates | C15: Open decisions, compliance checklist, and official sources
B17: EDITABLE PLAN INPUTS
B18: Plan start date | C18: 46258 | D18: Change this date; weekly dates recalculate.
B19: Selected scenario | C19: Base | D19: Lean = R18,000; Base = R36,000; Growth = R72,000.
B20: Operating model | C20: TO CONFIRM | D20: Clinic-led care, research supply, cosmetics, supplements, or education.
B21: Primary conversion | C21: WhatsApp / web enquiry | D21: Replace with consultation, research enquiry, quote, waitlist, or compliant sale.
B22: Priority geography | C22: South Africa | D22: Refine to city/region if fulfilment or service coverage is limited.
B24: UNIT ECONOMICS INPUTS
B25: Gross profit per conversion | D25: Enter real gross profit, fulfilment, payment cost, desired contribution, and observed conversion rate before scaling media. The maximum affordable acquisition figures update automatically. These are management thresholds, not revenue forecasts.
B26: Fulfilment cost per conversion
B27: Payment cost per conversion
B28: Desired contribution per conversion
B29: Qualified-enquiry-to-conversion rate | C29: 0.25
B31: Maximum affordable CAC | C31: =IF(COUNTA(C25:C28)<4,"INPUT REQUIRED",MAX(0,C25-C26-C27-C28))
B32: Maximum qualified-enquiry cost | C32: =IF(OR(NOT(ISNUMBER(C31)),C29=""),"INPUT REQUIRED",C31*C29)
B34: SCENARIO SUMMARY
B35: Scenario | C35: 90-day budget | D35: Conditional paid media | E35: Foundation/content | F35: Recommended use
B36: Lean | C36: ='90-Day Budget'!C18 | D36: ='90-Day Budget'!C14 | E36: =C36-D36 | F36: Founder-led validation with minimal suppliers
B37: Base | C37: ='90-Day Budget'!D18 | D37: ='90-Day Budget'!D14 | E37: =C37-D37 | F37: Recommended controlled launch and learning plan
B38: Growth | C38: ='90-Day Budget'!E18 | D38: ='90-Day Budget'!E14 | E38: =C38-D38 | F38: Only after proven eligibility, economics, and capacity
B42: Professional note
B43: This workbook is a planning tool, not legal, regulatory, medical, pharmacy, tax, or financial advice. Confirm product status, licensing, claims, privacy, platform eligibility, fulfilment capacity, supplier pricing, and unit economics with appropriately qualified professionals before launch.

Sheet 90-Day Budget
B2: 90-Day Marketing Budget
B3: All figures are planning assumptions in South African rand. Actual spend and variance fields are editable.
B5: SCENARIO AND BASE PHASING
B6: Category | C6: Lean | D6: Base | E6: Growth | F6: Base: Days 1–30 | G6: Base: Days 31–60 | H6: Base: Days 61–90 | I6: Actual total | J6: Variance to Base | K6: Actual status | L6: Purpose / release condition
B7: Compliance and professional review | C7: 1500 | D7: 3000 | E7: 4000 | F7: 2500 | G7: 500 | H7: 0 | J7: =IF(I7="","",I7-D7) | K7: Not started | L7: Verify model, claims, registrations, policies, and scripts
B8: Website and landing-page work | C8: 2500 | D8: 4500 | E8: 7000 | F8: 3500 | G8: 500 | H8: 500 | J8: =IF(I8="","",I8-D8) | K8: Not started | L8: Build or improve one trustworthy conversion path
B9: Analytics, CRM, and tracking | C9: 1000 | D9: 2000 | E9: 3000 | F9: 1500 | G9: 250 | H9: 250 | J9: =IF(I9="","",I9-D9) | K9: Not started | L9: Events, UTMs, dashboard, source and consent records
B10: SEO and content production | C10: 4000 | D10: 7500 | E10: 14000 | F10: 2500 | G10: 2500 | H10: 2500 | J10: =IF(I10="","",I10-D10) | K10: Not started | L10: Hub, six articles, research, editing, and on-page SEO
B11: Organic social production | C11: 3000 | D11: 5000 | E11: 10000 | F11: 1500 | G11: 1750 | H11: 1750 | J11: =IF(I11="","",I11-D11) | K11: Not started | L11: Weekly video, carousel, FAQ, editing, and scheduling
B12: Google Search media | C12: 3500 | D12: 7500 | E12: 23000 | F12: 0 | G12: 3000 | H12: 4500 | J12: =IF(I12="","",I12-D12) | K12: Not started | L12: Release only after eligibility, tracking, and landing-page gates
B13: Creative/media reserve | C13: 0 | D13: 1500 | E13: 4000 | F13: 500 | G13: 500 | H13: 500 | J13: =IF(I13="","",I13-D13) | K13: Not started | L13: Approved variations, photography, and format adaptation
B14: Email/WhatsApp software | C14: 500 | D14: 750 | E14: 1000 | F14: 250 | G14: 250 | H14: 250 | J14: =IF(I14="","",I14-D14) | K14: Not started | L14: Consent-based lead response and follow-up tools
B15: Conversion optimization | C15: 0 | D15: 0 | E15: 3000 | F15: 0 | G15: 0 | H15: 0 | J15: =IF(I15="","",I15-D15) | K15: Not started | L15: Growth tests after sufficient traffic and clean data
B16: Contingency | C16: 2000 | D16: 4250 | E16: 3000 | F16: 750 | G16: 1750 | H16: 1750 | J16: =IF(I16="","",I16-D16) | K16: Not started | L16: Unexpected fixes; not automatic media spend
B18: TOTAL | C18: =SUM(C7:C16) | D18: =SUM(D7:D16) | E18: =SUM(E7:E16) | F18: =SUM(F7:F16) | G18: =SUM(G7:G16) | H18: =SUM(H7:H16) | I18: =SUM(I7:I16) | J18: =IF(I18="","",I18-D18) | L18: Totals must reconcile before approval.
B21: BASE BUDGET MONTHLY SUMMARY
B22: Period | C22: Planned spend | D22: Share of base budget | E22: Primary purpose
B23: Days 1–30 | C23: =SUM(F7:F16) | D23: =C23/$C$26 | E23: Operating model, compliance, conversion path, analytics, trust pages, soft launch
B24: Days 31–60 | C24: =SUM(G7:G16) | D24: =C24/$C$26 | E24: Message validation, conditional search test, content, lead-quality review
B25: Days 61–90 | C25: =SUM(H7:H16) | D25: =C25/$C$26 | E25: Concentrate on winning cluster, conversion, referrals, decision
B26: TOTAL | C26: =SUM(C23:C25) | D26: =SUM(D23:D25) | E26: Base 90-day plan
B29: IF GOOGLE SEARCH IS NOT ELIGIBLE BY DAY 31
B30: Reallocation category | C30: Amount | D30: Condition
B31: Additional search content | C31: 3000 | D31: Build deeper coverage of the best compliant topic cluster
B32: Partner/referral outreach | C32: 2000 | D32: Information pack, outreach support, and relationship follow-up
B33: Conversion improvements | C33: 1500 | D33: Improve page clarity, form completion, trust proof, and response flow
B34: Compliance or technical fixes | C34: 1000 | D34: Resolve the documented gate preventing launch
B35: TOTAL | C35: =SUM(C31:C34)

Sheet Weekly Plan
B2: 13-Week Action Programme
B3: Update owner and status every Friday. Dates flow from Overview!C18.
B5: Week | C5: Start date | D5: Phase | E5: Objective | F5: Key actions | G5: Primary evidence/KPI | H5: Compliance or decision gate | I5: Owner | J5: Status
B6: 1 | C6: =Overview!$C$18+(1-1)*7 | D6: Foundation | E6: Lock the business model | F6: Select one operating model and audience; list every product/service; verify status, stock, capacity, margin, geography, and CTA; open claim register and risk log; assign owners. | G6: Signed brief; offer table; economics entered | H6: No public claim until model, evidence, audience, and approval are recorded. | I6: George / assign | J6: Planned
B7: 2 | C7: =Overview!$C$18+(2-1)*7 | D7: Foundation | E7: Build the conversion path | F7: Audit or create landing page; add clear CTA, privacy notice, consent text, thank-you state, WhatsApp routing, lead fields, and response script; test mobile and desktop. | G7: Successful test enquiry and notification | H7: Destination and response script must match the selected operating model. | I7: George / assign | J7: Planned
B8: 3 | C8: =Overview!$C$18+(3-1)*7 | D8: Foundation | E8: Establish trust and measurement | F8: Publish team/responsibility, how-it-works, documentation/safety, FAQ, and evidence pages; install GA4 and Search Console; define UTMs and conversion events. | G8: Pages live; events tested; source captured | H8: Do not collect unnecessary health or sensitive data in marketing forms. | I8: George / assign | J8: Planned
B9: 4 | C9: =Overview!$C$18+(4-1)*7 | D9: Foundation | E9: Soft launch organically | F9: Publish first hub article and three social assets; invite a small known audience and relevant partners; log questions, objections, complaints, and opt-ins. | G9: 10–20 interactions or outreach responses | H9: All public assets approved; no unresolved high-risk claim. | I9: George / assign | J9: Planned
B10: 5 | C10: =Overview!$C$18+(5-1)*7 | D10: Validation | E10: Select first demand cluster | F10: Review site queries, Search Console, comments, enquiries, and search-result patterns; select one compliant intent cluster; create matching page and exclusions. | G10: One cluster, page, CTA, and exclusions | H10: Complete Google/platform eligibility assessment before media release. | I10: George / assign | J10: Planned
B11: 6 | C11: =Overview!$C$18+(6-1)*7 | D11: Validation | E11: Launch controlled acquisition | F11: If eligible, launch one Google Search campaign at R100–R150/day; otherwise execute SEO outreach and partner referrals; publish three social assets and one article. | G11: Attributed traffic; response time measured | H11: No restricted product terms as a workaround; pause if account or landing page is ineligible. | I11: George / assign | J11: Planned
B12: 7 | C12: =Overview!$C$18+(7-1)*7 | D12: Validation | E12: Improve lead quality | F12: Review every search term and enquiry; add negatives; pause irrelevant terms; revise qualification questions and response script; interview at least three prospects or partners. | G12: Reasons for qualified/unqualified outcomes | H12: No individualized medical advice or unapproved claims in replies. | I12: George / assign | J12: Planned
B13: 8 | C13: =Overview!$C$18+(8-1)*7 | D13: Validation | E13: Improve conversion | F13: Test one headline or CTA; strengthen trust proof and FAQ; publish objection-handling content; send first permission-based follow-up. | G13: Test result; qualified rate and abandonment | H13: Only one controlled page variable changes; consent and opt-out remain intact. | I13: George / assign | J13: Planned
B14: 9 | C14: =Overview!$C$18+(9-1)*7 | D14: Optimization | E14: Expand the winning cluster | F14: Build one supporting article and one decision guide around best qualified-intent theme; strengthen internal links; create three derivative social posts. | G14: Growth in relevant engagement or enquiries | H14: Expansion stays within approved model and evidence scope. | I14: George / assign | J14: Planned
B15: 10 | C15: =Overview!$C$18+(10-1)*7 | D15: Optimization | E15: Strengthen trust and conversion | F15: Add approved process proof or representative testimonials if lawful; simplify the form; improve response speed; audit mobile experience. | G15: Improved completion or lower abandonment | H15: No misleading testimonials, outcomes, before/after claims, or hidden material connections. | I15: George / assign | J15: Planned
B16: 11 | C16: =Overview!$C$18+(11-1)*7 | D16: Optimization | E16: Build referral leverage | F16: Contact 15–25 relevant partners appropriate to the model; supply transparent one-page information pack; record introductions, status, terms, and compliance notes. | G16: Partner pipeline and next steps | H16: Referral arrangement, claims, data sharing, and commercial disclosure reviewed. | I16: George / assign | J16: Planned
B17: 12 | C17: =Overview!$C$18+(12-1)*7 | D17: Optimization | E17: Run final controlled test | F17: Shift allowable media and content toward the best source/page; pause weak terms and formats; validate capacity before increasing demand. | G17: Spend concentrated on evidence-backed activity | H17: Capacity, unit economics, policy status, and complaint rate support any increase. | I17: George / assign | J17: Planned
B18: 13 | C18: =Overview!$C$18+(13-1)*7 | D18: Decision | E18: Reconcile and decide | F18: Reconcile spend, traffic, enquiries, qualified outcomes, conversions, revenue, contribution, stock/capacity, complaints, opt-outs, and policy events; write next plan. | G18: Scale, revise, or stop decision approved | H18: No scale decision without four weeks of reliable data and affordable qualified enquiries. | I18: George / assign | J18: Planned

Sheet Content Calendar
B2: 90-Day Content Calendar
B3: Three useful items per week. All topics and CTAs require claim-register approval before publication.
B5: Week | C5: Publish date | D5: Day | E5: Channel | F5: Format | G5: Topic / working title | H5: Pillar | I5: CTA | J5: Approval gate | K5: Owner | L5: Status
B6: 1 | C6: =Overview!$C$18+(1-1)*7+1 | D6: Tue | E6: Instagram + TikTok | F6: Video | G6: What business model is George building—and why model clarity matters | H6: Model clarity | I6: Relevant guide or permission-based enquiry | J6: Claim register approved | K6: Assign | L6: Planned
B7: 1 | C7: =Overview!$C$18+(1-1)*7+3 | D7: Thu | E7: Instagram + LinkedIn | F7: Carousel | G7: Five facts to confirm before publishing any peptide-related claim | H7: Evidence literacy | I7: Relevant guide or permission-based enquiry | J7: Claim register approved | K7: Assign | L7: Planned
B8: 1 | C8: =Overview!$C$18+(1-1)*7+5 | D8: Sat | E8: Website + Instagram | F8: FAQ | G8: What George can answer online and what requires a qualified professional | H8: FAQ and boundaries | I8: Relevant guide or permission-based enquiry | J8: Claim register approved | K8: Assign | L8: Planned
B9: 2 | C9: =Overview!$C$18+(2-1)*7+1 | D9: Tue | E9: Instagram + TikTok | F9: Video | G9: What happens after a visitor submits an enquiry | H9: Process | I9: Relevant guide or permission-based enquiry | J9: Claim register approved | K9: Assign | L9: Planned
B10: 2 | C10: =Overview!$C$18+(2-1)*7+3 | D10: Thu | E10: Instagram + LinkedIn | F10: Carousel | G10: A privacy-conscious enquiry form: what it should and should not ask | H10: Process | I10: Relevant guide or permission-based enquiry | J10: Claim register approved | K10: Assign | L10: Planned
B11: 2 | C11: =Overview!$C$18+(2-1)*7+5 | D11: Sat | E11: Website + Instagram | F11: FAQ | G11: Consultation, research enquiry, quote, or waitlist: choosing the right next step | H11: Model clarity | I11: Relevant guide or permission-based enquiry | J11: Claim register approved | K11: Assign | L11: Planned
B12: 3 | C12: =Overview!$C$18+(3-1)*7+1 | D12: Tue | E12: Instagram + TikTok | F12: Video | G12: How to tell evidence from marketing language | H12: Evidence literacy | I12: Relevant guide or permission-based enquiry | J12: Claim register approved | K12: Assign | L12: Planned
B13: 3 | C13: =Overview!$C$18+(3-1)*7+3 | D13: Thu | E13: Instagram + LinkedIn | F13: Carousel | G13: A simple evidence-level ladder: approved information to unverified claim | H13: Evidence literacy | I13: Relevant guide or permission-based enquiry | J13: Claim register approved | K13: Assign | L13: Planned
B14: 3 | C14: =Overview!$C$18+(3-1)*7+5 | D14: Sat | E14: Website + Instagram | F14: FAQ | G14: Why a source link does not automatically prove a commercial claim | H14: Evidence literacy | I14: Relevant guide or permission-based enquiry | J14: Claim register approved | K14: Assign | L14: Planned
B15: 4 | C15: =Overview!$C$18+(4-1)*7+1 | D15: Tue | E15: Instagram + TikTok | F15: Video | G15: The provider-verification questions every South African customer should ask | H15: Provider verification | I15: Relevant guide or permission-based enquiry | J15: Claim register approved | K15: Assign | L15: Planned
B16: 4 | C16: =Overview!$C$18+(4-1)*7+3 | D16: Thu | E16: Instagram + LinkedIn | F16: Carousel | G16: Provider checklist: responsibility, status, documentation, privacy, and follow-up | H16: Provider verification | I16: Relevant guide or permission-based enquiry | J16: Claim register approved | K16: Assign | L16: Planned
B17: 4 | C17: =Overview!$C$18+(4-1)*7+5 | D17: Sat | E17: Website + Instagram | F17: FAQ | G17: What should a transparent how-it-works page explain? | H17: Process | I17: Relevant guide or permission-based enquiry | J17: Claim register approved | K17: Assign | L17: Planned
B18: 5 | C18: =Overview!$C$18+(5-1)*7+1 | D18: Tue | E18: Instagram + TikTok | F18: Video | G18: How to choose one search topic without overpromising | H18: South African relevance | I18: Relevant guide or permission-based enquiry | J18: Claim register approved | K18: Assign | L18: Planned
B19: 5 | C19: =Overview!$C$18+(5-1)*7+3 | D19: Thu | E19: Instagram + LinkedIn | F19: Carousel | G19: Search intent: education, consultation, research, or product purchase | H19: Model clarity | I19: Relevant guide or permission-based enquiry | J19: Claim register approved | K19: Assign | L19: Planned
B20: 5 | C20: =Overview!$C$18+(5-1)*7+5 | D20: Sat | E20: Website + Instagram | F20: FAQ | G20: Why the destination page must match the ad or post | H20: Process | I20: Relevant guide or permission-based enquiry | J20: Claim register approved | K20: Assign | L20: Planned
B21: 6 | C21: =Overview!$C$18+(6-1)*7+1 | D21: Tue | E21: Instagram + TikTok | F21: Video | G21: How to read a batch report or COA without overstating it | H21: Quality/documentation | I21: Relevant guide or permission-based enquiry | J21: Claim register approved | K21: Assign | L21: Planned
B22: 6 | C22: =Overview!$C$18+(6-1)*7+3 | D22: Thu | E22: Instagram + LinkedIn | F22: Carousel | G22: COA reading checklist: identity, batch, date, method, and limits | H22: Quality/documentation | I22: Relevant guide or permission-based enquiry | J22: Claim register approved | K22: Assign | L22: Planned
B23: 6 | C23: =Overview!$C$18+(6-1)*7+5 | D23: Sat | E23: Website + Instagram | F23: FAQ | G23: What a COA can and cannot establish | H23: Quality/documentation | I23: Relevant guide or permission-based enquiry | J23: Claim register approved | K23: Assign | L23: Planned
B24: 7 | C24: =Overview!$C$18+(7-1)*7+1 | D24: Tue | E24: Instagram + TikTok | F24: Video | G24: The difference between a click and a qualified enquiry | H24: Process | I24: Relevant guide or permission-based enquiry | J24: Claim register approved | K24: Assign | L24: Planned
B25: 7 | C25: =Overview!$C$18+(7-1)*7+3 | D25: Thu | E25: Instagram + LinkedIn | F25: Carousel | G25: The lead-quality review: source, intent, fit, outcome, and permission | H25: Process | I25: Relevant guide or permission-based enquiry | J25: Claim register approved | K25: Assign | L25: Planned
B26: 7 | C26: =Overview!$C$18+(7-1)*7+5 | D26: Sat | E26: Website + Instagram | F26: FAQ | G26: Why follower count is not the launch KPI | H26: FAQ and boundaries | I26: Relevant guide or permission-based enquiry | J26: Claim register approved | K26: Assign | L26: Planned
B27: 8 | C27: =Overview!$C$18+(8-1)*7+1 | D27: Tue | E27: Instagram + TikTok | F27: Video | G27: The most common questions from George’s first month | H27: FAQ and boundaries | I27: Relevant guide or permission-based enquiry | J27: Claim register approved | K27: Assign | L27: Planned
B28: 8 | C28: =Overview!$C$18+(8-1)*7+3 | D28: Thu | E28: Instagram + LinkedIn | F28: Carousel | G28: Objection map: status, evidence, process, timing, and cost | H28: FAQ and boundaries | I28: Relevant guide or permission-based enquiry | J28: Claim register approved | K28: Assign | L28: Planned
B29: 8 | C29: =Overview!$C$18+(8-1)*7+5 | D29: Sat | E29: Website + Instagram | F29: FAQ | G29: How quickly should an enquiry receive a human response? | H29: Process | I29: Relevant guide or permission-based enquiry | J29: Claim register approved | K29: Assign | L29: Planned
B30: 9 | C30: =Overview!$C$18+(9-1)*7+1 | D30: Tue | E30: Instagram + TikTok | F30: Video | G30: Research-use-only versus clinician-supervised care | H30: Model clarity | I30: Relevant guide or permission-based enquiry | J30: Claim register approved | K30: Assign | L30: Planned
B31: 9 | C31: =Overview!$C$18+(9-1)*7+3 | D31: Thu | E31: Instagram + LinkedIn | F31: Carousel | G31: Do not mix funnels: a visual guide to distinct operating models | H31: Model clarity | I31: Relevant guide or permission-based enquiry | J31: Claim register approved | K31: Assign | L31: Planned
B32: 9 | C32: =Overview!$C$18+(9-1)*7+5 | D32: Sat | E32: Website + Instagram | F32: FAQ | G32: Why the same CTA cannot serve every peptide business model | H32: Model clarity | I32: Relevant guide or permission-based enquiry | J32: Claim register approved | K32: Assign | L32: Planned
B33: 10 | C33: =Overview!$C$18+(10-1)*7+1 | D33: Tue | E33: Instagram + TikTok | F33: Video | G33: What trustworthy process proof looks like | H33: Provider verification | I33: Relevant guide or permission-based enquiry | J33: Claim register approved | K33: Assign | L33: Planned
B34: 10 | C34: =Overview!$C$18+(10-1)*7+3 | D34: Thu | E34: Instagram + LinkedIn | F34: Carousel | G34: Trust signals that can be verified versus vague badges | H34: Provider verification | I34: Relevant guide or permission-based enquiry | J34: Claim register approved | K34: Assign | L34: Planned
B35: 10 | C35: =Overview!$C$18+(10-1)*7+5 | D35: Sat | E35: Website + Instagram | F35: FAQ | G35: When testimonials create risk or mislead | H35: FAQ and boundaries | I35: Relevant guide or permission-based enquiry | J35: Claim register approved | K35: Assign | L35: Planned
B36: 11 | C36: =Overview!$C$18+(11-1)*7+1 | D36: Tue | E36: Instagram + TikTok | F36: Video | G36: What a good referral partner needs to know about George | H36: Provider verification | I36: Relevant guide or permission-based enquiry | J36: Claim register approved | K36: Assign | L36: Planned
B37: 11 | C37: =Overview!$C$18+(11-1)*7+3 | D37: Thu | E37: Instagram + LinkedIn | F37: Carousel | G37: Partner information pack: model, audience, boundaries, process, contact | H37: Process | I37: Relevant guide or permission-based enquiry | J37: Claim register approved | K37: Assign | L37: Planned
B38: 11 | C38: =Overview!$C$18+(11-1)*7+5 | D38: Sat | E38: Website + Instagram | F38: FAQ | G38: How commercial relationships should be disclosed | H38: FAQ and boundaries | I38: Relevant guide or permission-based enquiry | J38: Claim register approved | K38: Assign | L38: Planned
B39: 12 | C39: =Overview!$C$18+(12-1)*7+1 | D39: Tue | E39: Instagram + TikTok | F39: Video | G39: What the first 90 days have taught us | H39: Process | I39: Relevant guide or permission-based enquiry | J39: Claim register approved | K39: Assign | L39: Planned
B40: 12 | C40: =Overview!$C$18+(12-1)*7+3 | D40: Thu | E40: Instagram + LinkedIn | F40: Carousel | G40: The winning topic: what the data shows and what remains unknown | H40: Evidence literacy | I40: Relevant guide or permission-based enquiry | J40: Claim register approved | K40: Assign | L40: Planned
B41: 12 | C41: =Overview!$C$18+(12-1)*7+5 | D41: Sat | E41: Website + Instagram | F41: FAQ | G41: Why George is concentrating rather than adding more platforms | H41: Process | I41: Relevant guide or permission-based enquiry | J41: Claim register approved | K41: Assign | L41: Planned
B42: 13 | C42: =Overview!$C$18+(13-1)*7+1 | D42: Tue | E42: Instagram + TikTok | F42: Video | G42: Scale, revise, or stop: the day-90 decision | H42: Process | I42: Relevant guide or permission-based enquiry | J42: Claim register approved | K42: Assign | L42: Planned
...

Sheet KPI Tracker
B2: Weekly KPI and Economics Tracker
B3: Yellow cells are weekly inputs. Formula columns calculate automatically. Use qualified outcomes and contribution—not reach—as the decision basis.
B5: Week | C5: Start date | D5: Planned spend | E5: Actual spend | F5: Sessions | G5: Ad clicks | H5: Enquiries | I5: Qualified enquiries | J5: Consultations/quotes | K5: Conversions | L5: Revenue | M5: CPC | N5: Visit→enquiry | O5: Qualified rate | P5: Cost/qualified | Q5: CAC | R5: ROAS | S5: Median response (min) | T5: Content published | U5: Complaints/policy events | V5: Decision
B6: 1 | C6: =Overview!$C$18+(1-1)*7 | D6: 4000 | M6: =IFERROR(E6/G6,"") | N6: =IFERROR(H6/F6,"") | O6: =IFERROR(I6/H6,"") | P6: =IFERROR(E6/I6,"") | Q6: =IFERROR(E6/K6,"") | R6: =IFERROR(L6/E6,"") | V6: Review
B7: 2 | C7: =Overview!$C$18+(2-1)*7 | D7: 3500 | M7: =IFERROR(E7/G7,"") | N7: =IFERROR(H7/F7,"") | O7: =IFERROR(I7/H7,"") | P7: =IFERROR(E7/I7,"") | Q7: =IFERROR(E7/K7,"") | R7: =IFERROR(L7/E7,"") | V7: Review
B8: 3 | C8: =Overview!$C$18+(3-1)*7 | D8: 3500 | M8: =IFERROR(E8/G8,"") | N8: =IFERROR(H8/F8,"") | O8: =IFERROR(I8/H8,"") | P8: =IFERROR(E8/I8,"") | Q8: =IFERROR(E8/K8,"") | R8: =IFERROR(L8/E8,"") | V8: Review
B9: 4 | C9: =Overview!$C$18+(4-1)*7 | D9: 2000 | M9: =IFERROR(E9/G9,"") | N9: =IFERROR(H9/F9,"") | O9: =IFERROR(I9/H9,"") | P9: =IFERROR(E9/I9,"") | Q9: =IFERROR(E9/K9,"") | R9: =IFERROR(L9/E9,"") | V9: Review
B10: 5 | C10: =Overview!$C$18+(5-1)*7 | D10: 2500 | M10: =IFERROR(E10/G10,"") | N10: =IFERROR(H10/F10,"") | O10: =IFERROR(I10/H10,"") | P10: =IFERROR(E10/I10,"") | Q10: =IFERROR(E10/K10,"") | R10: =IFERROR(L10/E10,"") | V10: Review
B11: 6 | C11: =Overview!$C$18+(6-1)*7 | D11: 2800 | M11: =IFERROR(E11/G11,"") | N11: =IFERROR(H11/F11,"") | O11: =IFERROR(I11/H11,"") | P11: =IFERROR(E11/I11,"") | Q11: =IFERROR(E11/K11,"") | R11: =IFERROR(L11/E11,"") | V11: Review
B12: 7 | C12: =Overview!$C$18+(7-1)*7 | D12: 2800 | M12: =IFERROR(E12/G12,"") | N12: =IFERROR(H12/F12,"") | O12: =IFERROR(I12/H12,"") | P12: =IFERROR(E12/I12,"") | Q12: =IFERROR(E12/K12,"") | R12: =IFERROR(L12/E12,"") | V12: Review
B13: 8 | C13: =Overview!$C$18+(8-1)*7 | D13: 2900 | M13: =IFERROR(E13/G13,"") | N13: =IFERROR(H13/F13,"") | O13: =IFERROR(I13/H13,"") | P13: =IFERROR(E13/I13,"") | Q13: =IFERROR(E13/K13,"") | R13: =IFERROR(L13/E13,"") | V13: Review
B14: 9 | C14: =Overview!$C$18+(9-1)*7 | D14: 2800 | M14: =IFERROR(E14/G14,"") | N14: =IFERROR(H14/F14,"") | O14: =IFERROR(I14/H14,"") | P14: =IFERROR(E14/I14,"") | Q14: =IFERROR(E14/K14,"") | R14: =IFERROR(L14/E14,"") | V14: Review
B15: 10 | C15: =Overview!$C$18+(10-1)*7 | D15: 3000 | M15: =IFERROR(E15/G15,"") | N15: =IFERROR(H15/F15,"") | O15: =IFERROR(I15/H15,"") | P15: =IFERROR(E15/I15,"") | Q15: =IFERROR(E15/K15,"") | R15: =IFERROR(L15/E15,"") | V15: Review
B16: 11 | C16: =Overview!$C$18+(11-1)*7 | D16: 3000 | M16: =IFERROR(E16/G16,"") | N16: =IFERROR(H16/F16,"") | O16: =IFERROR(I16/H16,"") | P16: =IFERROR(E16/I16,"") | Q16: =IFERROR(E16/K16,"") | R16: =IFERROR(L16/E16,"") | V16: Review
B17: 12 | C17: =Overview!$C$18+(12-1)*7 | D17: 2500 | M17: =IFERROR(E17/G17,"") | N17: =IFERROR(H17/F17,"") | O17: =IFERROR(I17/H17,"") | P17: =IFERROR(E17/I17,"") | Q17: =IFERROR(E17/K17,"") | R17: =IFERROR(L17/E17,"") | V17: Review
B18: 13 | C18: =Overview!$C$18+(13-1)*7 | D18: 700 | M18: =IFERROR(E18/G18,"") | N18: =IFERROR(H18/F18,"") | O18: =IFERROR(I18/H18,"") | P18: =IFERROR(E18/I18,"") | Q18: =IFERROR(E18/K18,"") | R18: =IFERROR(L18/E18,"") | V18: Review
B20: TOTAL / BLENDED | D20: =SUM(D6:D18) | E20: =SUM(E6:E18) | F20: =SUM(F6:F18) | G20: =SUM(G6:G18) | H20: =SUM(H6:H18) | I20: =SUM(I6:I18) | J20: =SUM(J6:J18) | K20: =SUM(K6:K18) | L20: =SUM(L6:L18) | M20: =IFERROR(E20/G20,"") | N20: =IFERROR(H20/F20,"") | O20: =IFERROR(I20/H20,"") | P20: =IFERROR(E20/I20,"") | Q20: =IFERROR(E20/K20,"") | R20: =IFERROR(L20/E20,"") | S20: =SUM(S6:S18) | T20: =SUM(T6:T18) | U20: =SUM(U6:U18)
B23: DECISION THRESHOLDS
B24: Stop immediately | C24: Uncertain legal/platform eligibility; unapproved claim; sensitive-data failure; capacity failure; account warning or serious complaint.
B25: Fix before spend | C25: Unreliable tracking; response over one business day; majority irrelevant enquiries after a meaningful sample; mismatched ad and landing page.
B26: Hold steady | C26: Qualified enquiries exist, but sample size or economics are not stable.
B27: Scale carefully | C27: At least four weeks of reliable data; affordable qualified enquiries; economics and capacity work; no unresolved compliance event.

Sheet Claim Register
B2: Marketing Claim Register
B3: Record every material claim before it appears in an ad, post, page, email, script, message, or partner pack.
B5: Claim ID | C5: Proposed claim | D5: Source / evidence | E5: Evidence level | F5: Model scope | G5: Audience / placement | H5: Approval needed | I5: Approver | J5: Status | K5: Last review | L5: Notes / restrictions
B6: CLM-001 | C6: George clearly states the selected operating model and intended next step. | D6: Approved business brief and operating records | E6: Business fact | F6: TO CONFIRM | G6: All public pages and profiles | H6: Business + professional review | I6: Assign | J6: Review | L6: Replace model placeholder before publication.
B7: CLM-002 | C7: George explains the documentation or professional process customers should expect. | D7: Approved process map and current records | E7: Business fact | F7: TO CONFIRM | G7: Website, social, partner pack | H7: Business + professional review | I7: Assign | J7: Review | L7: Describe only controls that actually exist.
B8: CLM-003 | C8: George distinguishes evidence levels and the limits of available evidence. | D8: Cited authoritative or peer-reviewed sources | E8: Evidence education | F8: Education | G8: Evidence library and educational content | H8: Source + claim review | I8: Assign | J8: Review | L8: Do not convert source findings into product efficacy claims.
B9: CLM-004 | J9: Draft
B10: CLM-005 | J10: Draft
B11: CLM-006 | J11: Draft
B12: CLM-007 | J12: Draft
B13: CLM-008 | J13: Draft
B14: CLM-009 | J14: Draft
B15: CLM-010 | J15: Draft
B16: CLM-011 | J16: Draft
B17: CLM-012 | J17: Draft
B18: CLM-013 | J18: Draft
B19: CLM-014 | J19: Draft
B20: CLM-015 | J20: Draft
... B25: CLM-020 | J25: Draft

Sheet Assumptions & Gates
B2: Assumptions, Launch Gates, and Sources
B3: Replace assumptions with evidence in Week 1. A blocked critical gate prevents the affected activity from launching.
B5: OPEN BUSINESS ASSUMPTIONS
B6: Decision | C6: Working assumption | D6: Status | E6: Owner | F6: Evidence required | G6: Due | H6: Impact if unresolved | I6: Notes
B7: Country and launch area | C7: South Africa, English-first | D7: Review | E7: George | F7: Service/fulfilment area and customer profile | G7: Week 1 | H7: Medium
B8: Operating model | C8: TO CONFIRM | D8: Blocked | E8: George | F8: Approved legal and operational model | G8: Week 1 | H8: Critical | I8: Do not mix clinic, research, cosmetic, supplement, or education funnels.
B9: Product/service status | C9: Unknown | D9: Blocked | E9: George | F9: Registration/licensing/status documentation | G9: Week 1 | H9: Critical
B10: Primary audience | C10: Adults seeking credible local information | D10: Review | E10: George | F10: Defined segment and exclusions | G10: Week 1 | H10: High
B11: Primary CTA | C11: WhatsApp / web enquiry | D11: Review | E11: George | F11: Approved response and qualification flow | G11: Week 1 | H11: High
B12: Stock or service capacity | C12: Limited | D12: Blocked | E12: Operations | F12: Weekly capacity by offer and geography | G12: Week 1 | H12: Critical
B13: Unit economics | C13: Unknown | D13: Blocked | E13: Finance/George | F13: Gross profit, fulfilment, payment cost, contribution target | G13: Week 1 | H13: Critical | I13: Enter values on Overview.
B14: Website and analytics | C14: Needs audit | D14: Review | E14: Technical owner | F14: Domain access, page inventory, event tests | G14: Week 2 | H14: High
B17: CRITICAL LAUNCH GATES
B18: Gate | C18: Requirement | D18: Status | E18: Owner | F18: Evidence | G18: Review date | H18: Applies to | I18: Notes
B19: G1 Operating model | C19: One coherent model selected and documented | D19: Blocked | E19: George | H19: All marketing
B20: G2 Product/service status | C20: Status and lawful scope verified by appropriate professional | D20: Blocked | E20: Assign | H20: Claims and conversion
B21: G3 Claim register | C21: Every material claim has source, scope, approver, and status | D21: Blocked | E21: Assign | H21: All public assets
B22: G4 Website match | C22: Destination, offer, CTA, and privacy wording match the approved model | D22: Blocked | E22: Assign | H22: Website and paid media
B23: G5 Tracking | C23: Events, source, outcome, and consent records tested | D23: Blocked | E23: Assign | H23: Campaign launch
B24: G6 Lead response | C24: Approved script, response owner, and escalation path exist | D24: Blocked | E24: Assign | H24: Enquiry generation
B25: G7 Capacity | C25: Stock/service capacity and response standards support demand | D25: Blocked | E25: Operations | H25: Spend release
B26: G8 Google eligibility | C26: Applicable licensing/accreditation and Google certification confirmed | D26: Review | E26: Assign | H26: Google paid media | I26: Prescription drugs may not appear in South Africa ads or landing pages under the cited policy.
B27: G9 Meta eligibility | C27: Exact offer independently assessed against current policy | D27: Blocked | E27: Assign | H27: Meta paid media | I27: Base plan excludes direct prescription-drug promotion for South Africa.
B28: G10 TikTok eligibility | C28: Exact offer independently assessed against current policy | D28: Blocked | E28: Assign | H28: TikTok paid media | I28: Base plan excludes paid promotion; prescription medicines are listed as not allowed in South Africa.
B29: G11 POPIA/direct marketing | C29: Consent, purpose, source, retention, opt-out, and suppression process documented | D29: Blocked | E29: Assign | H29: Email and WhatsApp
B30: G12 Economics | C30: Affordable CPL/CAC thresholds entered and approved | D30: Blocked | E30: Finance/George | H30: Media scale
B33: OFFICIAL SOURCES
B34: Source | C34: URL | D34: Planning use | E34: Accessed
B35: SAHPRA: Guidelines for Advertisement of Medicines and Health Products | C35: https://www.sahpra.org.za/wp-content/uploads/2022/06/SAHPGL-INSP-RC-07-Guidelines-for-Advertisement-of-Medicines-and-Health-Products.pdf | D35: Registration, accuracy, evidence, and advertising controls | E35: 46252
B36: Google Ads: Healthcare and medicines — South Africa | C36: https://support.google.com/adspolicy/answer/176031?hl=en | D36: Online pharmacy/telemedicine and certification restrictions | E36: 46252
B37: Meta: Drugs and Pharmaceuticals | C37: https://transparency.meta.com/policies/ad-standards/restricted-goods-services/drugs-pharmaceuticals/ | D37: Country, authorization, and prescription-drug advertising limits | E37: 46252
B38: TikTok: Healthcare and Pharmaceuticals | C38: https://ads.tiktok.com/help/article/tiktok-ads-policy-healthcare-pharmaceuticals | D38: South Africa healthcare-category restrictions | E38: 46252
B39: Information Regulator: Guidance notes | C39: https://inforegulator.org.za/guidance-notes/ | D39: Direct marketing and POPIA governance | E39: 46252
